Workbook

Sheet Report
D1: Sheet Validation | J1: =IF(SUM(AF:AF)=0,"SHEET NOT YET STARTED",IF(SUM(AG:AG)>0,"SHEET NOT COMPLETE","SHEET COMPLETE")) -> SHEET COMPLETE
D3: Report | AB3: Comments for Surveyors | AD3: Visibility | AE3: Sheet Validation to right | AF3: Check if any data is entered | AG3: Check if field needs to be completed
A4: =IF(AG4=1,"X","") | B4: 1 | AD4: Always show
A5: =IF(AG5=1,"X","") | B5: 1 | AD5: Always show
A6: =IF(AG6=1,"X","") | B6: 1 | D6: Client Name And Site Details | AB6: Will always show | AD6: Always show
A7: =IF(AG7=1,"X","") | B7: 1 | AD7: Always show
A8: =IF(AG8=1,"X","") | B8: 1 | D8: =Costing!E7 -> Finest Properties | AB8: Will always show (pre-populated) | AD8: Always show | AF8: =IF(D8<>"",1,0) -> 1 | AG8: =IF(AND(SUM(AF:AF)>0,OR(D8="",D8=0)),1,0) -> 0
A9: =IF(AG9=1,"X","") | B9: 1 | D9: =Costing!E8 -> Clive House | AB9: Will always show (pre-populated) | AD9: Always show | AF9: =IF(D9<>"",1,0) -> 1 | AG9: =IF(AND(SUM(AF:AF)>0,OR(D9="",D9=0)),1,0) -> 0
A10: =IF(AG10=1,"X","") | B10: 1 | D10: =Costing!E9 -> Appletree Lane | AB10: Will always show (pre-populated) | AD10: Always show | AF10: =IF(D10<>"",1,0) -> 1 | AG10: =IF(AND(SUM(AF:AF)>0,OR(D10="",D10=0)),1,0) -> 0
A11: =IF(AG11=1,"X","") | B11: 1 | D11: =Costing!E10 -> Corbridge | AB11: Will always show (pre-populated) | AD11: Always show | AF11: =IF(D11<>"",1,0) -> 1 | AG11: =IF(AND(SUM(AF:AF)>0,OR(D11="",D11=0)),1,0) -> 0
A12: =IF(AG12=1,"X","") | B12: 1 | D12: =Costing!E11 -> NE45 5DN | AB12: Will always show (pre-populated) | AD12: Always show | AF12: =IF(D12<>"",1,0) -> 1 | AG12: =IF(AND(SUM(AF:AF)>0,OR(D12="",D12=0)),1,0) -> 0
A13: =IF(AG13=1,"X","") | B13: 1 | D13: Internal Reference ID: | I13: =Costing!E4 -> PRONE455DN | AB13: Will always show (pre-populated) | AD13: Always show | AF13: =IF(I13<>"",1,0) -> 1 | AG13: =IF(AND(SUM(AF:AF)>0,OR(I13="",I13=0)),1,0) -> 0
A14: =IF(AG14=1,"X","") | B14: 1 | AD14: Always show
A15: =IF(AG15=1,"X","") | B15: 1 | AD15: Always show
A16: =IF(AG16=1,"X","") | B16: 1 | D16: Weather Conditions | AB16: Will always show | AD16: Always show
A17: =IF(AG17=1,"X","") | B17: 1 | D17: Date of Inspection: | K17: 45982 | AB17: ← Enter Data Here | AD17: Always show | AF17: =IF(K17<>"",1,0) -> 1 | AG17: =IF(AND(SUM(AF:AF)>0,K17=""),1,0) -> 0
A18: =IF(AG18=1,"X","") | B18: 1 | D18: The weather conditions were: | K18: Dry sunny | AB18: ← Enter Data Here | AD18: Always show | AF18: =IF(K18<>"",1,0) -> 1 | AG18: =IF(AND(SUM(AF:AF)>0,K18=""),1,0) -> 0
A19: =IF(AG19=1,"X","") | B19: 1 | D19: The weather temperature was: | K19: 3 | L19: (°C). | AB19: ← Enter Data Here | AD19: Always show | AF19: =IF(K19<>"",1,0) -> 1 | AG19: =IF(AND(SUM(AF:AF)>0,K19=""),1,0) -> 0
A20: =IF(AG20=1,"X","") | B20: 1 | D20: The Property | AB20: Will always show | AD20: Always show
A21: =IF(AG21=1,"X","") | B21: 0 | D21: Use the alt key and the mouse to 'snap' the image to the top and bottom of the cell for alignment. | AB21: This line will NOT show on the report | AD21: Always Hide
B22: 0 | D22: ↓ Image Section 1 ↓ | AB22: This line will NOT show on the report | AD22: Always Hide
A23: =IF(AG23=1,"X","") | B23: =IF(OR(D24="Show",Q24="Show"),1,0) -> 1 | AD23: Always show
A24: =IF(AG24=1,"X","") | B24: 0 | D24: Show | Q24: Show | AB24: ← Enter Image Visibility | AD24: Determined by surveyor | AF24: =IF(OR(D24="Show",D24="",Q24="Show",Q24=""),1,0) -> 1 | AG24: =IF(AND(SUM(AF:AF)>0,OR(D24="",Q24="")),1,0) -> 0
A25: =IF(AG25=1,"X","") | B25: =B23 -> 1 | AB25: ← Add Images | AD25: Determined by surveyor
A26: =IF(AG26=1,"X","") | B26: =B25 -> 1 | D26: Front Elevation | Q26: Side Elevation | AB26: ← Enter Images Descriptions | AD26: Determined by surveyor | AF26: =IF(OR(D24="Show",D24="",Q24="Show",Q24=""),1,0) -> 1 | AG26: =IF(AND(SUM(AF:AF)>0,OR(AND(D24="Show",D26=""),AND(Q24="Show",Q26=""))),1,0) -> 0
A27: =IF(AG27=1,"X","") | B27: =B26 -> 1 | AD27: Always show
B28: 0 | D28: ↑ Image Section 1 ↑ | AB28: This line will NOT show on the report | AD28: Always Hide
B29: 0 | D29: ↓ Image Section 1 ↓ | AB29: This line will NOT show on the report | AD29: Always Hide
A30: =IF(AG30=1,"X","") | B30: =IF(OR(D31="Show",Q31="Show"),1,0) -> 1 | AD30: Always show
A31: =IF(AG31=1,"X","") | B31: 0 | D31: Show | Q31: Hide | AB31: ← Enter Image Visibility | AD31: Determined by surveyor | AF31: =IF(OR(D31="Show",D31="",Q31="Show",Q31=""),1,0) -> 1 | AG31: =IF(AND(SUM(AF:AF)>0,OR(D31="",Q31="")),1,0) -> 0
A32: =IF(AG32=1,"X","") | B32: =B30 -> 1 | AB32: ← Add Images | AD32: Determined by surveyor
A33: =IF(AG33=1,"X","") | B33: =B32 -> 1 | D33: Ensuite | AB33: ← Enter Images Descriptions | AD33: Determined by surveyor | AF33: =IF(OR(D31="Show",D31="",Q31="Show",Q31=""),1,0) -> 1 | AG33: =IF(AND(SUM(AF:AF)>0,OR(AND(D31="Show",D33=""),AND(Q31="Show",Q33=""))),1,0) -> 0
A34: =IF(AG34=1,"X","") | B34: =B33 -> 1 | AD34: Always show
B35: 0 | D35: ↑ Image Section 1 ↑ | AB35: This line will NOT show on the report | AD35: Always Hide
A36: =IF(AG36=1,"X","") | B36: 1 | D36: The property is a: | M36: Stone and slate | AB36: ← Enter Data Here | AD36: Always show | AF36: =IF(M36<>"",1,0) -> 1 | AG36: =IF(AND(SUM(AF:AF)>0,M36=""),1,0) -> 0
A37: =IF(AG37=1,"X","") | B37: 1 | D37: The property is constructed of : | M37: Detached | AB37: ← Enter Data Here | AD37: Always show | AF37: =IF(M37<>"",1,0) -> 1 | AG37: =IF(AND(SUM(AF:AF)>0,M37=""),1,0) -> 0
A38: =IF(AG38=1,"X","") | B38: 1 | D38: The property was built approximately : | M38: 1800s | AB38: ← Enter Data Here | AD38: Always show | AF38: =IF(M38<>"",1,0) -> 1 | AG38: =IF(AND(SUM(AF:AF)>0,M38=""),1,0) -> 0
A39: =IF(AG39=1,"X","") | B39: 1 | D39: The Survey/Specific Defects Inspection | AB39: Will always show | AD39: Always show
A40: =IF(AG40=1,"X","") | B40: 1 | D40: In accordance with your specific instructions, we carried out a survey of the above property for problems with mould, mildew & condensation. | AB40: Will always show | AD40: Always show
A41: =IF(AG41=1,"X","") | B41: 1 | D41: Our findings and proposals are set out below and should be read in conjunction with the enclosed document 'General Notes for clients and Health and Safety precautions'. | AB41: Will always show | AD41: Always show
...

Sheet Costing
B1: Sheet Validation | E1: =IF(SUM(AT:AT)=0,"SHEET NOT YET STARTED",IF(SUM(AU:AU)>0,"SHEET NOT COMPLETE","SHEET COMPLETE")) -> SHEET COMPLETE | AS1: Sheet Validation to right | AT1: Check if any data is entered | AU1: Check if field needs to be completed
A3: =IF(AU3=1,"X","") | B3: Enquiry Details
A4: =IF(AU4=1,"X","") | B4: Enquiry number | E4: =IF([1]Details!$C$4=0,"",UPPER([1]Details!$C$4)) -> PRONE455DN | AT4: =IF(E4<>"",1,0) -> 1 | AU4: =IF(AND(SUM(AT:AT)>0,E4=""),1,0) -> 0
A5: =IF(AU5=1,"X","")
A6: =IF(AU6=1,"X","") | B6: Site Details
A7: =IF(AU7=1,"X","") | B7: =[1]Details!$B$7 -> Client Name | E7: =IF([1]Details!$C$7=0,"",PROPER([1]Details!$C$7)) -> Finest Properties | AT7: =IF(E7<>"",1,0) -> 1 | AU7: =IF(AND(SUM(AT:AT)>0,E7=""),1,0) -> 0
A8: =IF(AU8=1,"X","") | B8: =[1]Details!$B$8 -> First Line of site address | E8: =IF([1]Details!$C$8=0,"",PROPER([1]Details!$C$8)) -> Clive House | AT8: =IF(E8<>"",1,0) -> 1 | AU8: =IF(AND(SUM(AT:AT)>0,E8=""),1,0) -> 0
A9: =IF(AU9=1,"X","") | B9: =[1]Details!$B$9 -> Town / City | E9: =IF([1]Details!$C$9=0,"",PROPER([1]Details!$C$9)) -> Appletree Lane | AT9: =IF(E9<>"",1,0) -> 1 | AU9: =IF(AND(SUM(AT:AT)>0,E9=""),1,0) -> 0
A10: =IF(AU10=1,"X","") | B10: =[1]Details!$B$10 -> County | E10: =IF([1]Details!$C$10=0,"",PROPER([1]Details!$C$10)) -> Corbridge | AT10: =IF(E10<>"",1,0) -> 1 | AU10: =IF(AND(SUM(AT:AT)>0,E10=""),1,0) -> 0
A11: =IF(AU11=1,"X","") | B11: =[1]Details!$B$11 -> Site Post Code | E11: =IF([1]Details!$C$11=0,"",UPPER([1]Details!$C$11)) -> NE45 5DN | AT11: =IF(E11<>"",1,0) -> 1 | AU11: =IF(AND(SUM(AT:AT)>0,E11=""),1,0) -> 0
A12: =IF(AU12=1,"X","")
A13: =IF(AU13=1,"X","") | B13: Survey Carried Out By
A14: =IF(AU14=1,"X","") | B14: Surveyor | E14: =IF([1]Details!$C$16=0,"",[1]Details!$C$16) -> Steven Robinson | AT14: =IF(E14<>"",1,0) -> 1 | AU14: =IF(AND(SUM(AT:AT)>0,E14=""),1,0) -> 0
A15: =IF(AU15=1,"X","")
A16: =IF(AU16=1,"X","") | B16: CONDENSATION SHEET
A17: =IF(AU17=1,"X","") | B17: Materials | F17: Area/No. | G17: UOM | H17: Default Mats Cost | I17: Adjusted Mats Cost | J17: M/U | K17: Mats Tot | M17: Labour | N17: Hour Mult | O17: Total Hours | P17: Default Lab Cost | Q17: Adjusted Lab Cost | R17: LMU | S17: Lab Total | T17: Line total | U17: Contractor Materials | V17: Contractor hours pay
A18: =IF(AU18=1,"X","")
A20: =IF(AU20=1,"X","") | B20: PIV - LOFT UNIT | M20: =B20 -> PIV - LOFT UNIT | U20: =B20 -> PIV - LOFT UNIT
A21: =IF(AU21=1,"X","") | B21: VA Pozidry loft unit - heated | F21: 1 | G21: Each | H21: 324.13 | I21: =(H21/100)*(100+$F$25) -> 307.9235 | J21: 0.4 | K21: =F21*I21*(1+J21) -> 431.0929 | M21: =B21 -> VA Pozidry loft unit - heated | N21: 2.5 | O21: =F21*N21 -> 2.5 | P21: =$D$107 -> 30.63 | Q21: =(P21/100)*(100+$F$25) -> 29.0985 | R21: 4 | S21: =(O21*Q21*(1+R21)) -> 363.73125 | T21: =K21+S21 -> 794.82415 | U21: =F21*H21*1.1 -> 356.543 | V21: =O21*$E$107 -> 70 | AT21: =IF(F21<>"",1,0) -> 1 | AU21: =IF(AND(SUM(AT:AT)>0,F21=""),1,0) -> 0
A22: =IF(AU22=1,"X","") | B22: VA Pozidry loft unit - unheated | F22: 0 | G22: Each | H22: 309.96 | I22: =(H22/100)*(100+$F$25) -> 294.462 | J22: 0.4 | K22: =F22*I22*(1+J22) -> 0 | M22: =B22 -> VA Pozidry loft unit - unheated | N22: 2.5 | O22: =F22*N22 -> 0 | P22: =$D$107 -> 30.63 | Q22: =(P22/100)*(100+$F$25) -> 29.0985 | R22: 4 | S22: =(O22*Q22*(1+R22)) -> 0 | T22: =K22+S22 -> 0 | U22: =F22*H22*1.1 -> 0 | V22: =O22*$E$107 -> 0 | AT22: =IF(F22<>"",1,0) -> 1 | AU22: =IF(AND(SUM(AT:AT)>0,F22=""),1,0) -> 0
A23: =IF(AU23=1,"X","") | B23: Electrical Pack - fused spur, cable, JB | F23: 0 | G23: Each | H23: 12.46 | I23: =(H23/100)*(100+$F$25) -> 11.837 | J23: 0.3 | K23: =F23*I23*(1+J23) -> 0 | L23: 0.25 | M23: =B23 -> Electrical Pack - fused spur, cable, JB | N23: 1.5 | O23: =F23*N23 -> 0 | P23: =$D$107 -> 30.63 | Q23: =(P23/100)*(100+$F$25) -> 29.0985 | R23: 1 | S23: =(O23*Q23*(1+R23)) -> 0 | T23: =K23+S23 -> 0 | U23: =F23*H23*1.1 -> 0 | V23: =O23*$E$107 -> 0 | AT23: =IF(F23<>"",1,0) -> 1 | AU23: =IF(AND(SUM(AT:AT)>0,F23=""),1,0) -> 0
A24: =IF(AU24=1,"X","") | B24: Sarkvents | F24: 0 | G24: Each | H24: 3 | I24: =(H24/100)*(100+$F$25) -> 2.85 | J24: 0.3 | K24: =F24*I24*(1+J24) -> 0 | L24: 0.25 | M24: =B24 -> Sarkvents | N24: 0.08 | O24: =F24*N24 -> 0 | P24: =$D$107 -> 30.63 | Q24: =(P24/100)*(100+$F$25) -> 29.0985 | R24: 1 | S24: =(O24*Q24*(1+R24)) -> 0 | T24: =K24+S24 -> 0 | U24: =F24*H24*1.1 -> 0 | V24: =O24*$E$107 -> 0 | AT24: =IF(F24<>"",1,0) -> 1 | AU24: =IF(AND(SUM(AT:AT)>0,F24=""),1,0) -> 0
A25: =IF(AU25=1,"X","") | B25: Section Price Adjustment % | F25: -5 | J25: Totals | K25: =SUM(K21:K24) -> 431.0929 | M25: Totals | O25: =SUM(O21:O24) -> 2.5 | S25: =SUM(S21:S24) -> 363.73125 | T25: =SUM(T21:T24) -> 794.82415 | U25: =SUM(U21:U24) -> 356.543 | V25: =SUM(V21:V24) -> 70
A27: =IF(AU27=1,"X","") | B27: PIV - WALL MOUNTED UNIT | M27: =B27 -> PIV - WALL MOUNTED UNIT | U27: =B27 -> PIV - WALL MOUNTED UNIT
A28: =IF(AU28=1,"X","") | B28: VA Pozidry Compact wall mounted unit | F28: 0 | G28: Each | H28: 273.74 | I28: =(H28/100)*(100+$F$42) -> 273.74 | J28: 0.4 | K28: =F28*I28*(1+J28) -> 0 | L28: 0.75 | M28: =B28 -> VA Pozidry Compact wall mounted unit | N28: 4 | O28: =F28*N28 -> 0 | P28: =$D$107 -> 30.63 | Q28: =(P28/100)*(100+$F$42) -> 30.63 | R28: 3 | S28: =(O28*Q28*(1+R28)) -> 0 | T28: =K28+S28 -> 0 | U28: =F28*H28*1.1 -> 0 | V28: =O28*$E$107 -> 0 | AT28: =IF(F28<>"",1,0) -> 1 | AU28: =IF(AND(SUM(AT:AT)>0,F28=""),1,0) -> 0
A29: =IF(AU29=1,"X","") | B29: Electrical Pack - fused spur, cable, JB | F29: 0 | G29: Each | H29: 12.46 | I29: =(H29/100)*(100+$F$42) -> 12.46 | J29: 0.3 | K29: =F29*I29*(1+J29) -> 0 | L29: 0.25 | M29: =B29 -> Electrical Pack - fused spur, cable, JB | N29: 1.5 | O29: =F29*N29 -> 0 | P29: =$D$107 -> 30.63 | Q29: =(P29/100)*(100+$F$42) -> 30.63 | R29: 1 | S29: =(O29*Q29*(1+R29)) -> 0 | T29: =K29+S29 -> 0 | U29: =F29*H29*1.1 -> 0 | V29: =O29*$E$107 -> 0 | AT29: =IF(F29<>"",1,0) -> 1 | AU29: =IF(AND(SUM(AT:AT)>0,F29=""),1,0) -> 0
A30: =IF(AU30=1,"X","") | B30: Ducting - 1m length | F30: 0 | G30: Each | H30: 3.85 | I30: =(H30/100)*(100+$F$42) -> 3.85 | J30: 0.3 | K30: =F30*I30*(1+J30) -> 0 | L30: 0.25 | M30: =B30 -> Ducting - 1m length | N30: 0.1 | O30: =F30*N30 -> 0 | P30: =$D$107 -> 30.63 | Q30: =(P30/100)*(100+$F$42) -> 30.63 | R30: 1 | S30: =(O30*Q30*(1+R30)) -> 0 | T30: =K30+S30 -> 0 | U30: =F30*H30*1.1 -> 0 | V30: =O30*$E$107 -> 0 | AT30: =IF(F30<>"",1,0) -> 1 | AU30: =IF(AND(SUM(AT:AT)>0,F30=""),1,0) -> 0
A31: =IF(AU31=1,"X","") | B31: Ducting - round elbow | F31: 0 | G31: Each | H31: 2.78 | I31: =(H31/100)*(100+$F$42) -> 2.78 | J31: 0.3 | K31: =F31*I31*(1+J31) -> 0 | L31: 0.25 | M31: =B31 -> Ducting - round elbow | N31: 0.1 | O31: =F31*N31 -> 0 | P31: =$D$107 -> 30.63 | Q31: =(P31/100)*(100+$F$42) -> 30.63 | R31: 1 | S31: =(O31*Q31*(1+R31)) -> 0 | T31: =K31+S31 -> 0 | U31: =F31*H31*1.1 -> 0 | V31: =O31*$E$107 -> 0 | AT31: =IF(F31<>"",1,0) -> 1 | AU31: =IF(AND(SUM(AT:AT)>0,F31=""),1,0) -> 0
A32: =IF(AU32=1,"X","") | B32: Ducting - round - straight conn | F32: 0 | G32: Each | H32: 0.52 | I32: =(H32/100)*(100+$F$42) -> 0.52 | J32: 0.3 | K32: =F32*I32*(1+J32) -> 0 | L32: 0.25 | M32: =B32 -> Ducting - round - straight conn | N32: 0.1 | O32: =F32*N32 -> 0 | P32: =$D$107 -> 30.63 | Q32: =(P32/100)*(100+$F$42) -> 30.63 | R32: 1 | S32: =(O32*Q32*(1+R32)) -> 0 | T32: =K32+S32 -> 0 | U32: =F32*H32*1.1 -> 0 | V32: =O32*$E$107 -> 0 | AT32: =IF(F32<>"",1,0) -> 1 | AU32: =IF(AND(SUM(AT:AT)>0,F32=""),1,0) -> 0
A33: =IF(AU33=1,"X","") | B33: Ducting - round 1m | F33: 0 | G33: Each | H33: 3.85 | I33: =(H33/100)*(100+$F$42) -> 3.85 | J33: 0.3 | K33: =F33*I33*(1+J33) -> 0 | L33: 0.25 | M33: =B33 -> Ducting - round 1m | N33: 0.1 | O33: =F33*N33 -> 0 | P33: =$D$107 -> 30.63 | Q33: =(P33/100)*(100+$F$42) -> 30.63 | R33: 1 | S33: =(O33*Q33*(1+R33)) -> 0 | T33: =K33+S33 -> 0 | U33: =F33*H33*1.1 -> 0 | V33: =O33*$E$107 -> 0 | AT33: =IF(F33<>"",1,0) -> 1 | AU33: =IF(AND(SUM(AT:AT)>0,F33=""),1,0) -> 0
A34: =IF(AU34=1,"X","") | B34: Ducting - flat to round adaptor | F34: 0 | G34: Each | H34: 1.63 | I34: =(H34/100)*(100+$F$42) -> 1.63 | J34: 0.3 | K34: =F34*I34*(1+J34) -> 0 | L34: 0.25 | M34: =B34 -> Ducting - flat to round adaptor | N34: 0.1 | O34: =F34*N34 -> 0 | P34: =$D$107 -> 30.63 | Q34: =(P34/100)*(100+$F$42) -> 30.63 | R34: 1 | S34: =(O34*Q34*(1+R34)) -> 0 | T34: =K34+S34 -> 0 | U34: =F34*H34*1.1 -> 0 | V34: =O34*$E$107 -> 0 | AT34: =IF(F34<>"",1,0) -> 1 | AU34: =IF(AND(SUM(AT:AT)>0,F34=""),1,0) -> 0
A35: =IF(AU35=1,"X","") | B35: Ducting - flat straight connector | F35: 0 | G35: Each | H35: 1.14 | I35: =(H35/100)*(100+$F$42) -> 1.14 | J35: 0.3 | K35: =F35*I35*(1+J35) -> 0 | L35: 0.25 | M35: =B35 -> Ducting - flat straight connector | N35: 0.1 | O35: =F35*N35 -> 0 | P35: =$D$107 -> 30.63 | Q35: =(P35/100)*(100+$F$42) -> 30.63 | R35: 1 | S35: =(O35*Q35*(1+R35)) -> 0 | T35: =K35+S35 -> 0 | U35: =F35*H35*1.1 -> 0 | V35: =O35*$E$107 -> 0 | AT35: =IF(F35<>"",1,0) -> 1 | AU35: =IF(AND(SUM(AT:AT)>0,F35=""),1,0) -> 0
A36: =IF(AU36=1,"X","") | B36: Ducting - flat horizontal bend | F36: 0 | G36: Each | H36: 3.01 | I36: =(H36/100)*(100+$F$42) -> 3.01 | J36: 0.3 | K36: =F36*I36*(1+J36) -> 0 | L36: 0.25 | M36: =B36 -> Ducting - flat horizontal bend | N36: 0.1 | O36: =F36*N36 -> 0 | P36: =$D$107 -> 30.63 | Q36: =(P36/100)*(100+$F$42) -> 30.63 | R36: 1 | S36: =(O36*Q36*(1+R36)) -> 0 | T36: =K36+S36 -> 0 | U36: =F36*H36*1.1 -> 0 | V36: =O36*$E$107 -> 0 | AT36: =IF(F36<>"",1,0) -> 1 | AU36: =IF(AND(SUM(AT:AT)>0,F36=""),1,0) -> 0
A37: =IF(AU37=1,"X","") | B37: Ducting - flat vertical bend | F37: 0 | G37: Each | H37: 3.01 | I37: =(H37/100)*(100+$F$42) -> 3.01 | J37: 0.3 | K37: =F37*I37*(1+J37) -> 0 | L37: 0.25 | M37: =B37 -> Ducting - flat vertical bend | N37: 0.1 | O37: =F37*N37 -> 0 | P37: =$D$107 -> 30.63 | Q37: =(P37/100)*(100+$F$42) -> 30.63 | R37: 1 | S37: =(O37*Q37*(1+R37)) -> 0 | T37: =K37+S37 -> 0 | U37: =F37*H37*1.1 -> 0 | V37: =O37*$E$107 -> 0 | AT37: =IF(F37<>"",1,0) -> 1 | AU37: =IF(AND(SUM(AT:AT)>0,F37=""),1,0) -> 0
A38: =IF(AU38=1,"X","") | B38: Ducting - flat - 1m | F38: 0 | G38: Each | H38: 2.87 | I38: =(H38/100)*(100+$F$42) -> 2.87 | J38: 0.3 | K38: =F38*I38*(1+J38) -> 0 | L38: 0.25 | M38: =B38 -> Ducting - flat - 1m | N38: 0.1 | O38: =F38*N38 -> 0 | P38: =$D$107 -> 30.63 | Q38: =(P38/100)*(100+$F$42) -> 30.63 | R38: 1 | S38: =(O38*Q38*(1+R38)) -> 0 | T38: =K38+S38 -> 0 | U38: =F38*H38*1.1 -> 0 | V38: =O38*$E$107 -> 0 | AT38: =IF(F38<>"",1,0) -> 1 | AU38: =IF(AND(SUM(AT:AT)>0,F38=""),1,0) -> 0
A39: =IF(AU39=1,"X","") | B39: Ducting - insulated flexi (3m Length) | F39: 0 | G39: Each | H39: 2.5 | I39: =(H39/100)*(100+$F$42) -> 2.5 | J39: 0.3 | K39: =F39*I39*(1+J39) -> 0 | L39: 0.25 | M39: =B39 -> Ducting - insulated flexi (3m Length) | N39: 0.1 | O39: =F39*N39 -> 0 | P39: =$D$107 -> 30.63 | Q39: =(P39/100)*(100+$F$42) -> 30.63 | R39: 1 | S39: =(O39*Q39*(1+R39)) -> 0 | T39: =K39+S39 -> 0 | U39: =F39*H39*1.1 -> 0 | V39: =O39*$E$107 -> 0 | AT39: =IF(F39<>"",1,0) -> 1 | AU39: =IF(AND(SUM(AT:AT)>0,F39=""),1,0) -> 0
... A41: =IF(AU41=1,"X","") | B41: Diamond core 107mm hole | F41: 0 | G41: Each | H41: 0 | I41: =(H41/100)*(100+$F$42) -> 0 | J41: 0.3 | K41: =F41*I41*(1+J41) -> 0 | L41: 0.25 | M41: =B41 -> Diamond core 107mm hole | N41: 2 | O41: =F41*N41 -> 0 | P41: =$D$107 -> 30.63 | Q41: =(P41/100)*(100+$F$42) -> 30.63 | R41: 1 | S41: =(O41*Q41*(1+R41)) -> 0 | T41: =K41+S41 -> 0 | U41: =F41*H41*1.1 -> 0 | V41: =O41*$E$107 -> 0 | AT41: =IF(F41<>"",1,0) -> 1 | AU41: =IF(AND(SUM(AT:AT)>0,F41=""),1,0) -> 0
A42: =IF(AU42=1,"X","") | B42: Section Price Adjustment % | F42: 0 | J42: Totals | K42: =SUM(K28:K41) -> 0 | M42: Totals | O42: =SUM(O28:O41) -> 0 | S42: =SUM(S28:S41) -> 0 | T42: =SUM(T28:T41) -> 0 | U42: =SUM(U28:U41) -> 0 | V42: =SUM(V28:V41) -> 0
A44: =IF(AU44=1,"X","") | B44: TRICKLE AND BOOST HUMIDISTAT FAN | M44: =B44 -> TRICKLE AND BOOST HUMIDISTAT FAN | U44: =B44 -> TRICKLE AND BOOST HUMIDISTAT FAN
A45: =IF(AU45=1,"X","") | B45: Trickle and boost humidistat fan (greenwood) | F45: 5 | G45: Each | H45: 70.2 | I45: =(H45/100)*(100+$F$49) -> 70.2 | J45: 0.3 | K45: =F45*I45*(1+J45) -> 456.3 | L45: 0.75 | M45: =B45 -> Trickle and boost humidistat fan (greenwood) | N45: 1.5 | O45: =F45*N45 -> 7.5 | P45: =$D$107 -> 30.63 | Q45: =(P45/100)*(100+$F$49) -> 30.63 | R45: 1 | S45: =(O45*Q45*(1+R45)) -> 459.45 | T45: =K45+S45 -> 915.75 | U45: =F45*H45*1.1 -> 386.1 | V45: =O45*$E$107 -> 210 | AT45: =IF(F45<>"",1,0) -> 1 | AU45: =IF(AND(SUM(AT:AT)>0,F45=""),1,0) -> 0
...

Sheet Customer Summary
B1: =IF(Costing!E1="SHEET NOT COMPLETE","PLEASE COMPLETE COSTING BEFORE SUPPLYING A PRICE","")
B2: Customer Pricing Summary
B3: # | C3: Area of Works | D3: Optional Item? | E3: Price (Without Optional items) | F3: Price (With Optional Items)
B4: 1 | C4: Condensation control: Supply and install Loft Dryaire system & required accessories | D4: No | E4: =IF(D4="Yes","Optional",F4) -> 794.82415 | F4: =IF(SUMIFS('CF CSV Upload'!P:P,'CF CSV Upload'!A:A,'Customer Summary'!C4,'CF CSV Upload'!Q:Q,"Yes")=0,"n/a",SUMIFS('CF CSV Upload'!P:P,'CF CSV Upload'!A:A,'Customer Summary'!C4,'CF CSV Upload'!Q:Q,"Yes")) -> 794.82415
B5: =B4+1 -> 2 | C5: Condensation control: Supply and install Wall Mounted Dryaire system & required accessories | D5: No | E5: =IF(D5="Yes","Optional",F5) -> n/a | F5: =IF(SUMIFS('CF CSV Upload'!P:P,'CF CSV Upload'!A:A,'Customer Summary'!C5,'CF CSV Upload'!Q:Q,"Yes")=0,"n/a",SUMIFS('CF CSV Upload'!P:P,'CF CSV Upload'!A:A,'Customer Summary'!C5,'CF CSV Upload'!Q:Q,"Yes")) -> n/a
B6: =B5+1 -> 3 | C6: Condensation control: Supply and install Trickle & Boost Fan | D6: No | E6: =IF(D6="Yes","Optional",F6) -> 915.75 | F6: =IF(SUMIFS('CF CSV Upload'!P:P,'CF CSV Upload'!A:A,'Customer Summary'!C6,'CF CSV Upload'!Q:Q,"Yes")=0,"n/a",SUMIFS('CF CSV Upload'!P:P,'CF CSV Upload'!A:A,'Customer Summary'!C6,'CF CSV Upload'!Q:Q,"Yes")) -> 915.75
B7: =B6+1 -> 4 | C7: Condensation control: Supply and install Dryaire Cpass Insulated Pullcord Passive Vent | D7: No | E7: =IF(D7="Yes","Optional",F7) -> n/a | F7: =IF(SUMIFS('CF CSV Upload'!P:P,'CF CSV Upload'!A:A,'Customer Summary'!C7,'CF CSV Upload'!Q:Q,"Yes")=0,"n/a",SUMIFS('CF CSV Upload'!P:P,'CF CSV Upload'!A:A,'Customer Summary'!C7,'CF CSV Upload'!Q:Q,"Yes")) -> n/a
B8: =B7+1 -> 5 | C8: Condensation control: Supply and install Dryaire CVent | D8: No | E8: =IF(D8="Yes","Optional",F8) -> n/a | F8: =IF(SUMIFS('CF CSV Upload'!P:P,'CF CSV Upload'!A:A,'Customer Summary'!C8,'CF CSV Upload'!Q:Q,"Yes")=0,"n/a",SUMIFS('CF CSV Upload'!P:P,'CF CSV Upload'!A:A,'Customer Summary'!C8,'CF CSV Upload'!Q:Q,"Yes")) -> n/a
B9: =B8+1 -> 6 | C9: Joinery: Supply and fit boxwork for ducting | D9: Yes | E9: =IF(D9="Yes","Optional",F9) -> Optional | F9: =IF(SUMIFS('CF CSV Upload'!P:P,'CF CSV Upload'!A:A,'Customer Summary'!C9,'CF CSV Upload'!Q:Q,"Yes")=0,"n/a",SUMIFS('CF CSV Upload'!P:P,'CF CSV Upload'!A:A,'Customer Summary'!C9,'CF CSV Upload'!Q:Q,"Yes")) -> n/a
B10: =B9+1 -> 7 | C10: New hatch and ladder: Create larger opening, install new sturdy hatch and ladder to loft entry | D10: Yes | E10: =IF(D10="Yes","Optional",F10) -> Optional | F10: =IF(SUMIFS('CF CSV Upload'!P:P,'CF CSV Upload'!A:A,'Customer Summary'!C10,'CF CSV Upload'!Q:Q,"Yes")=0,"n/a",SUMIFS('CF CSV Upload'!P:P,'CF CSV Upload'!A:A,'Customer Summary'!C10,'CF CSV Upload'!Q:Q,"Yes")) -> n/a
B11: =B10+1 -> 8 | C11: Loft opening: Enlarge existing loft opening and install new hatch lid | D11: Yes | E11: =IF(D11="Yes","Optional",F11) -> Optional | F11: =IF(SUMIFS('CF CSV Upload'!P:P,'CF CSV Upload'!A:A,'Customer Summary'!C11,'CF CSV Upload'!Q:Q,"Yes")=0,"n/a",SUMIFS('CF CSV Upload'!P:P,'CF CSV Upload'!A:A,'Customer Summary'!C11,'CF CSV Upload'!Q:Q,"Yes")) -> n/a
B12: =B11+1 -> 9 | C12: Remedial treatments: Mould treatment | D12: No | E12: =IF(D12="Yes","Optional",F12) -> 95.79 | F12: =IF(SUMIFS('CF CSV Upload'!P:P,'CF CSV Upload'!A:A,'Customer Summary'!C12,'CF CSV Upload'!Q:Q,"Yes")=0,"n/a",SUMIFS('CF CSV Upload'!P:P,'CF CSV Upload'!A:A,'Customer Summary'!C12,'CF CSV Upload'!Q:Q,"Yes")) -> 95.79
B13: =B12+1 -> 10 | C13: Asbestos Testing | D13: Yes | E13: =IF(D13="Yes","Optional",F13) -> Optional | F13: =IF(SUMIFS('CF CSV Upload'!P:P,'CF CSV Upload'!A:A,'Customer Summary'!C13,'CF CSV Upload'!Q:Q,"Yes")=0,"n/a",SUMIFS('CF CSV Upload'!P:P,'CF CSV Upload'!A:A,'Customer Summary'!C13,'CF CSV Upload'!Q:Q,"Yes")) -> n/a
B14: =B13+1 -> 11 | C14: Airbricks | D14: No | E14: =IF(D14="Yes","Optional",F14) -> n/a | F14: =IF(SUMIFS('CF CSV Upload'!P:P,'CF CSV Upload'!A:A,'Customer Summary'!C14,'CF CSV Upload'!Q:Q,"Yes")=0,"n/a",SUMIFS('CF CSV Upload'!P:P,'CF CSV Upload'!A:A,'Customer Summary'!C14,'CF CSV Upload'!Q:Q,"Yes")) -> n/a
B15: =B14+1 -> 12 | C15: Project Specific Overheads | D15: No | E15: =IF(D15="Yes","Optional",F15) -> 139.932 | F15: =IF(SUMIFS('CF CSV Upload'!P:P,'CF CSV Upload'!A:A,'Customer Summary'!C15,'CF CSV Upload'!Q:Q,"Yes")=0,"n/a",SUMIFS('CF CSV Upload'!P:P,'CF CSV Upload'!A:A,'Customer Summary'!C15,'CF CSV Upload'!Q:Q,"Yes")) -> 139.932
B16: Totals
C17: Sub Total | E17: =SUM(E4:E15) -> 1946.2961 | F17: =SUM(F4:F15) -> 1946.2961
C18: Vat at 20% | E18: =E17*0.2 -> 389.25923 | F18: =F17*0.2 -> 389.25923
C19: Total | E19: =SUM(E17:E18) -> 2335.5554 | F19: =SUM(F17:F18) -> 2335.5554
C21: Start of works deposit at 50% | D21: Ex. VAT | E21: =E22/6*5 -> 973.14807 | F21: =F22/6*5 -> 973.14807
D22: Inc. VAT | E22: =E19*0.5 -> 1167.7777 | F22: =F19*0.5 -> 1167.7777

Sheet Office Notes
A1: Add notes below that the office need to consider when compiling the estimate and report.

Sheet CAF1 Form
B1: On Site Acceptance Form (CAF1).
B3: Enquiry ID:
B4: Client Name
B5: Address 1
B6: Address 2
B7: Address 3
B8: Address 4
B9: Postcode
B11: I wish to proceed with the woks specified below. (tick items required and total cost)
B13: Operation | I13: Price | K13: Tick
B14: Damp Proofing
B15: Timber treatments/replacements
B16: Condensation
B17: Wall Ties
B18: Other works
B19: Subtotal
B20: VAT
B21: Total
B22: Deposit
B24: I accept the company terms and conditions of contract which I have viewed at the link below and I have paid my deposit with this order.
B25: https://www.tyneteesdampproofing.co.uk/terms-and-conditions/
B27: I wish the work to commence before the 14 day cooling off period and waive my consumer rights (please sign to confirm)
B29: Signed: | I29: Date:

Sheet Sub Contractor Costs
B2: Sub Contractor Costs
B3: Project Details
B4: Enquiry number | D4: =Costing!E4 -> PRONE455DN
B5: =[1]Details!$B$7 -> Client Name | D5: =Costing!E7 -> Finest Properties
B6: =[1]Details!$B$8 -> First Line of site address | D6: =Costing!E8 -> Clive House
B7: =[1]Details!$B$9 -> Town / City | D7: =Costing!E9 -> Appletree Lane
B8: =[1]Details!$B$10 -> County | D8: =Costing!E10 -> Corbridge
B9: =[1]Details!$B$11 -> Site Post Code | D9: =Costing!E11 -> NE45 5DN
B10: # | C10: Area of Works | D10: Costs (Ex VAT) | E10: Assigned to / Comments: | G10: Total Projected Hours
B11: 1 | C11: ='Customer Summary'!C4 -> Condensation control: Supply and install Loft Dryaire system & required accessories | D11: =Costing!V25 -> 70 | G11: =Costing!O25 -> 2.5
B12: =B11+1 -> 2 | C12: ='Customer Summary'!C5 -> Condensation control: Supply and install Wall Mounted Dryaire system & required accessories | D12: =Costing!V42 -> 0 | G12: =Costing!O42 -> 0
B13: =B12+1 -> 3 | C13: ='Customer Summary'!C6 -> Condensation control: Supply and install Trickle & Boost Fan | D13: =Costing!V49 -> 210 | G13: =Costing!O49 -> 7.5
B14: =B13+1 -> 4 | C14: ='Customer Summary'!C7 -> Condensation control: Supply and install Dryaire Cpass Insulated Pullcord Passive Vent | D14: =Costing!V54 -> 0 | G14: =Costing!O54 -> 0
B15: =B14+1 -> 5 | C15: ='Customer Summary'!C8 -> Condensation control: Supply and install Dryaire CVent | D15: =Costing!V59 -> 0 | G15: =Costing!O59 -> 0
B16: =B15+1 -> 6 | C16: ='Customer Summary'!C9 -> Joinery: Supply and fit boxwork for ducting | D16: =Costing!V63 -> 0 | G16: =Costing!O63 -> 0
B17: =B16+1 -> 7 | C17: ='Customer Summary'!C10 -> New hatch and ladder: Create larger opening, install new sturdy hatch and ladder to loft entry | D17: =Costing!V67 -> 0 | G17: =Costing!V67 -> 0
B18: =B17+1 -> 8 | C18: ='Customer Summary'!C11 -> Loft opening: Enlarge existing loft opening and install new hatch lid | D18: =Costing!V71 -> 0 | G18: =Costing!V71 -> 0
B19: =B18+1 -> 9 | C19: ='Customer Summary'!C12 -> Remedial treatments: Mould treatment | D19: =Costing!V75 -> 42 | G19: =Costing!V75 -> 42
B20: =B19+1 -> 10 | C20: ='Customer Summary'!C13 -> Asbestos Testing | D20: =Costing!V79 -> 0 | G20: =Costing!V79 -> 0
B21: =B20+1 -> 11 | C21: ='Customer Summary'!C14 -> Airbricks | D21: =Costing!V85 -> 0 | G21: =Costing!V85 -> 0
C23: Total | D23: =SUM(D11:D22) -> 322 | G23: =SUM(G11:G22) -> 52

Sheet CF CSV Upload
A1: Section | B1: Section Description | C1: Item Name | D1: Quantity | E1: Unit Cost | F1: Unit | G1: Cost Code | H1: Markup | I1: Markup Type | J1: Item Type | K1: Is Taxable | L1: Is Optional | M1: Assigned To | N1: CF IGNORE - LINE VALUE | O1: CF IGNORE - Zero value Section Validation | P1: CF IGNORE - LINE VALUE FOR CUSTOMER SUMMARY | Q1: CF IGNORE - INCLUDE PRICE IN CUSTOMER SUMMARY
A2: ='Customer Summary'!C4 -> Condensation control: Supply and install Loft Dryaire system & required accessories | C2: =Costing!B21 -> VA Pozidry loft unit - heated | D2: =Costing!F21 -> 1 | E2: =Costing!I21 -> 307.9235 | F2: =Costing!G21 -> Each | G2: Condensation Materials | H2: =Costing!J21*100 -> 40 | I2: % | J2: MTL | K2: Yes | L2: No | M2: =IF(J2="MTL","Preservation Shop","") -> Preservation Shop | N2: =D2*E2 -> 307.9235 | O2: DELETE | P2: =N2*(1+(H2/100)) -> 431.0929 | Q2: No
A3: =A2 -> Condensation control: Supply and install Loft Dryaire system & required accessories | C3: =Costing!B22 -> VA Pozidry loft unit - unheated | D3: =Costing!F22 -> 0 | E3: =Costing!I22 -> 294.462 | F3: =Costing!G22 -> Each | G3: Condensation Materials | H3: =Costing!J22*100 -> 40 | I3: % | J3: MTL | K3: Yes | L3: No | M3: =IF(J3="MTL","Preservation Shop","") -> Preservation Shop | N3: =D3*E3 -> 0 | O3: DELETE | P3: =N3*(1+(H3/100)) -> 0 | Q3: No
A4: =A3 -> Condensation control: Supply and install Loft Dryaire system & required accessories | C4: =Costing!B23 -> Electrical Pack - fused spur, cable, JB | D4: =Costing!F23 -> 0 | E4: =Costing!I23 -> 11.837 | F4: =Costing!G23 -> Each | G4: Condensation Materials | H4: =Costing!J23*100 -> 30 | I4: % | J4: MTL | K4: Yes | L4: No | M4: =IF(J4="MTL","Preservation Shop","") -> Preservation Shop | N4: =D4*E4 -> 0 | O4: DELETE | P4: =N4*(1+(H4/100)) -> 0 | Q4: No
A5: =A4 -> Condensation control: Supply and install Loft Dryaire system & required accessories | C5: =Costing!B24 -> Sarkvents | D5: =Costing!F24 -> 0 | E5: =Costing!I24 -> 2.85 | F5: =Costing!G24 -> Each | G5: Condensation Materials | H5: =Costing!J24*100 -> 30 | I5: % | J5: MTL | K5: Yes | L5: No | M5: =IF(J5="MTL","Preservation Shop","") -> Preservation Shop | N5: =D5*E5 -> 0 | O5: DELETE | P5: =N5*(1+(H5/100)) -> 0 | Q5: No
A6: =A5 -> Condensation control: Supply and install Loft Dryaire system & required accessories | C6: =Costing!M21 -> VA Pozidry loft unit - heated | D6: =Costing!O21 -> 2.5 | E6: =Costing!Q21 -> 29.0985 | F6: Hours | G6: Condensation Labour | H6: =Costing!R21*100 -> 400 | I6: % | J6: LBR | K6: Yes | L6: No | M6: =IF(J6="MTL","Preservation Shop","") | N6: =D6*E6 -> 72.74625 | O6: DELETE | P6: =N6*(1+(H6/100)) -> 363.73125 | Q6: No
A7: =A6 -> Condensation control: Supply and install Loft Dryaire system & required accessories | C7: =Costing!M22 -> VA Pozidry loft unit - unheated | D7: =Costing!O22 -> 0 | E7: =Costing!Q22 -> 29.0985 | F7: Hours | G7: Condensation Labour | H7: =Costing!R22*100 -> 400 | I7: % | J7: LBR | K7: Yes | L7: No | M7: =IF(J7="MTL","Preservation Shop","") | N7: =D7*E7 -> 0 | O7: DELETE | P7: =N7*(1+(H7/100)) -> 0 | Q7: No
A8: =A7 -> Condensation control: Supply and install Loft Dryaire system & required accessories | C8: =Costing!M23 -> Electrical Pack - fused spur, cable, JB | D8: =Costing!O23 -> 0 | E8: =Costing!Q23 -> 29.0985 | F8: Hours | G8: Condensation Labour | H8: =Costing!R23*100 -> 100 | I8: % | J8: LBR | K8: Yes | L8: No | M8: =IF(J8="MTL","Preservation Shop","") | N8: =D8*E8 -> 0 | O8: DELETE | P8: =N8*(1+(H8/100)) -> 0 | Q8: No
A9: =A8 -> Condensation control: Supply and install Loft Dryaire system & required accessories | C9: =Costing!M24 -> Sarkvents | D9: =Costing!O24 -> 0 | E9: =Costing!Q24 -> 29.0985 | F9: Hours | G9: Condensation Labour | H9: =Costing!R24*100 -> 100 | I9: % | J9: LBR | K9: Yes | L9: No | M9: =IF(J9="MTL","Preservation Shop","") | N9: =D9*E9 -> 0 | O9: DELETE | P9: =N9*(1+(H9/100)) -> 0 | Q9: No
A10: =A9 -> Condensation control: Supply and install Loft Dryaire system & required accessories | C10: =_xlfn.CONCAT(A10," - Materials") -> Condensation control: Supply and install Loft Dryaire system & required accessories - Materials | D10: 1 | E10: =N10 -> 307.9235 | F10: EACH | G10: Condensation Materials | H10: =((P10-N10)/N10)*100 -> 40 | I10: % | J10: MTL | K10: Yes | L10: ='Customer Summary'!D4 -> No | M10: =IF(J10="MTL","Preservation Shop","") -> Preservation Shop | N10: =SUM(N2:N5) -> 307.9235 | O10: =IF(N10=0,"DELETE","LEAVE") -> LEAVE | P10: =SUM(P2:P5) -> 431.0929 | Q10: Yes
A11: =A10 -> Condensation control: Supply and install Loft Dryaire system & required accessories | C11: =_xlfn.CONCAT(A11," - Labour") -> Condensation control: Supply and install Loft Dryaire system & required accessories - Labour | D11: =SUM(D6:D9) -> 2.5 | E11: =N11/D11 -> 29.0985 | F11: Hours | G11: Condensation Labour | H11: =((P11-N11)/N11)*100 -> 400 | I11: % | J11: LBR | K11: Yes | L11: =L10 -> No | M11: =IF(J11="MTL","Preservation Shop","") | N11: =SUM(N6:N9) -> 72.74625 | O11: =IF(N11=0,"DELETE","LEAVE") -> LEAVE | P11: =SUM(P6:P9) -> 363.73125 | Q11: Yes
O12: DELETE
A13: ='Customer Summary'!C5 -> Condensation control: Supply and install Wall Mounted Dryaire system & required accessories | C13: =Costing!B28 -> VA Pozidry Compact wall mounted unit | D13: =Costing!F28 -> 0 | E13: =Costing!I28 -> 273.74 | F13: =Costing!G28 -> Each | G13: Condensation Materials | H13: =Costing!J28*100 -> 40 | I13: % | J13: MTL | K13: Yes | L13: No | M13: =IF(J13="MTL","Preservation Shop","") -> Preservation Shop | N13: =D13*E13 -> 0 | O13: DELETE | P13: =N13*(1+(H13/100)) -> 0 | Q13: No
A14: =A13 -> Condensation control: Supply and install Wall Mounted Dryaire system & required accessories | C14: =Costing!B29 -> Electrical Pack - fused spur, cable, JB | D14: =Costing!F29 -> 0 | E14: =Costing!I29 -> 12.46 | F14: =Costing!G29 -> Each | G14: Condensation Materials | H14: =Costing!J29*100 -> 30 | I14: % | J14: MTL | K14: Yes | L14: No | M14: =IF(J14="MTL","Preservation Shop","") -> Preservation Shop | N14: =D14*E14 -> 0 | O14: DELETE | P14: =N14*(1+(H14/100)) -> 0 | Q14: No
A15: =A14 -> Condensation control: Supply and install Wall Mounted Dryaire system & required accessories | C15: =Costing!B30 -> Ducting - 1m length | D15: =Costing!F30 -> 0 | E15: =Costing!I30 -> 3.85 | F15: =Costing!G30 -> Each | G15: Condensation Materials | H15: =Costing!J30*100 -> 30 | I15: % | J15: MTL | K15: Yes | L15: No | M15: =IF(J15="MTL","Preservation Shop","") -> Preservation Shop | N15: =D15*E15 -> 0 | O15: DELETE | P15: =N15*(1+(H15/100)) -> 0 | Q15: No
A16: =A15 -> Condensation control: Supply and install Wall Mounted Dryaire system & required accessories | C16: =Costing!B31 -> Ducting - round elbow | D16: =Costing!F31 -> 0 | E16: =Costing!I31 -> 2.78 | F16: =Costing!G31 -> Each | G16: Condensation Materials | H16: =Costing!J31*100 -> 30 | I16: % | J16: MTL | K16: Yes | L16: No | M16: =IF(J16="MTL","Preservation Shop","") -> Preservation Shop | N16: =D16*E16 -> 0 | O16: DELETE | P16: =N16*(1+(H16/100)) -> 0 | Q16: No
A17: =A16 -> Condensation control: Supply and install Wall Mounted Dryaire system & required accessories | C17: =Costing!B32 -> Ducting - round - straight conn | D17: =Costing!F32 -> 0 | E17: =Costing!I32 -> 0.52 | F17: =Costing!G32 -> Each | G17: Condensation Materials | H17: =Costing!J32*100 -> 30 | I17: % | J17: MTL | K17: Yes | L17: No | M17: =IF(J17="MTL","Preservation Shop","") -> Preservation Shop | N17: =D17*E17 -> 0 | O17: DELETE | P17: =N17*(1+(H17/100)) -> 0 | Q17: No
A18: =A17 -> Condensation control: Supply and install Wall Mounted Dryaire system & required accessories | C18: =Costing!B33 -> Ducting - round 1m | D18: =Costing!F33 -> 0 | E18: =Costing!I33 -> 3.85 | F18: =Costing!G33 -> Each | G18: Condensation Materials | H18: =Costing!J33*100 -> 30 | I18: % | J18: MTL | K18: Yes | L18: No | M18: =IF(J18="MTL","Preservation Shop","") -> Preservation Shop | N18: =D18*E18 -> 0 | O18: DELETE | P18: =N18*(1+(H18/100)) -> 0 | Q18: No
A19: =A18 -> Condensation control: Supply and install Wall Mounted Dryaire system & required accessories | C19: =Costing!B34 -> Ducting - flat to round adaptor | D19: =Costing!F34 -> 0 | E19: =Costing!I34 -> 1.63 | F19: =Costing!G34 -> Each | G19: Condensation Materials | H19: =Costing!J34*100 -> 30 | I19: % | J19: MTL | K19: Yes | L19: No | M19: =IF(J19="MTL","Preservation Shop","") -> Preservation Shop | N19: =D19*E19 -> 0 | O19: DELETE | P19: =N19*(1+(H19/100)) -> 0 | Q19: No
A20: =A19 -> Condensation control: Supply and install Wall Mounted Dryaire system & required accessories | C20: =Costing!B35 -> Ducting - flat straight connector | D20: =Costing!F35 -> 0 | E20: =Costing!I35 -> 1.14 | F20: =Costing!G35 -> Each | G20: Condensation Materials | H20: =Costing!J35*100 -> 30 | I20: % | J20: MTL | K20: Yes | L20: No | M20: =IF(J20="MTL","Preservation Shop","") -> Preservation Shop | N20: =D20*E20 -> 0 | O20: DELETE | P20: =N20*(1+(H20/100)) -> 0 | Q20: No
A21: =A20 -> Condensation control: Supply and install Wall Mounted Dryaire system & required accessories | C21: =Costing!B36 -> Ducting - flat horizontal bend | D21: =Costing!F36 -> 0 | E21: =Costing!I36 -> 3.01 | F21: =Costing!G36 -> Each | G21: Condensation Materials | H21: =Costing!J36*100 -> 30 | I21: % | J21: MTL | K21: Yes | L21: No | M21: =IF(J21="MTL","Preservation Shop","") -> Preservation Shop | N21: =D21*E21 -> 0 | O21: DELETE | P21: =N21*(1+(H21/100)) -> 0 | Q21: No
A22: =A21 -> Condensation control: Supply and install Wall Mounted Dryaire system & required accessories | C22: =Costing!B37 -> Ducting - flat vertical bend | D22: =Costing!F37 -> 0 | E22: =Costing!I37 -> 3.01 | F22: =Costing!G37 -> Each | G22: Condensation Materials | H22: =Costing!J37*100 -> 30 | I22: % | J22: MTL | K22: Yes | L22: No | M22: =IF(J22="MTL","Preservation Shop","") -> Preservation Shop | N22: =D22*E22 -> 0 | O22: DELETE | P22: =N22*(1+(H22/100)) -> 0 | Q22: No
A23: =A22 -> Condensation control: Supply and install Wall Mounted Dryaire system & required accessories | C23: =Costing!B38 -> Ducting - flat - 1m | D23: =Costing!F38 -> 0 | E23: =Costing!I38 -> 2.87 | F23: =Costing!G38 -> Each | G23: Condensation Materials | H23: =Costing!J38*100 -> 30 | I23: % | J23: MTL | K23: Yes | L23: No | M23: =IF(J23="MTL","Preservation Shop","") -> Preservation Shop | N23: =D23*E23 -> 0 | O23: DELETE | P23: =N23*(1+(H23/100)) -> 0 | Q23: No
A24: =A23 -> Condensation control: Supply and install Wall Mounted Dryaire system & required accessories | C24: =Costing!B39 -> Ducting - insulated flexi (3m Length) | D24: =Costing!F39 -> 0 | E24: =Costing!I39 -> 2.5 | F24: =Costing!G39 -> Each | G24: Condensation Materials | H24: =Costing!J39*100 -> 30 | I24: % | J24: MTL | K24: Yes | L24: No | M24: =IF(J24="MTL","Preservation Shop","") -> Preservation Shop | N24: =D24*E24 -> 0 | O24: DELETE | P24: =N24*(1+(H24/100)) -> 0 | Q24: No
A25: =A24 -> Condensation control: Supply and install Wall Mounted Dryaire system & required accessories | C25: =Costing!B40 -> Grille | D25: =Costing!F40 -> 0 | E25: =Costing!I40 -> 2.42 | F25: =Costing!G40 -> Each | G25: Condensation Materials | H25: =Costing!J40*100 -> 30 | I25: % | J25: MTL | K25: Yes | L25: No | M25: =IF(J25="MTL","Preservation Shop","") -> Preservation Shop | N25: =D25*E25 -> 0 | O25: DELETE | P25: =N25*(1+(H25/100)) -> 0 | Q25: No
A26: =A25 -> Condensation control: Supply and install Wall Mounted Dryaire system & required accessories | C26: =Costing!B41 -> Diamond core 107mm hole | D26: =Costing!F41 -> 0 | E26: =Costing!I41 -> 0 | F26: =Costing!G41 -> Each | G26: Condensation Materials | H26: =Costing!J41*100 -> 30 | I26: % | J26: MTL | K26: Yes | L26: No | M26: =IF(J26="MTL","Preservation Shop","") -> Preservation Shop | N26: =D26*E26 -> 0 | O26: DELETE | P26: =N26*(1+(H26/100)) -> 0 | Q26: No
A27: =A26 -> Condensation control: Supply and install Wall Mounted Dryaire system & required accessories | C27: =Costing!M28 -> VA Pozidry Compact wall mounted unit | D27: =Costing!O28 -> 0 | E27: =Costing!Q28 -> 30.63 | F27: Hours | G27: Condensation Labour | H27: =Costing!R28*100 -> 300 | I27: % | J27: LBR | K27: Yes | L27: No | M27: =IF(J27="MTL","Preservation Shop","") | N27: =D27*E27 -> 0 | O27: DELETE | P27: =N27*(1+(H27/100)) -> 0 | Q27: No
A28: =A27 -> Condensation control: Supply and install Wall Mounted Dryaire system & required accessories | C28: =Costing!M29 -> Electrical Pack - fused spur, cable, JB | D28: =Costing!O29 -> 0 | E28: =Costing!Q29 -> 30.63 | F28: Hours | G28: Condensation Labour | H28: =Costing!R29*100 -> 100 | I28: % | J28: LBR | K28: Yes | L28: No | M28: =IF(J28="MTL","Preservation Shop","") | N28: =D28*E28 -> 0 | O28: DELETE | P28: =N28*(1+(H28/100)) -> 0 | Q28: No
A29: =A28 -> Condensation control: Supply and install Wall Mounted Dryaire system & required accessories | C29: =Costing!M30 -> Ducting - 1m length | D29: =Costing!O30 -> 0 | E29: =Costing!Q30 -> 30.63 | F29: Hours | G29: Condensation Labour | H29: =Costing!R30*100 -> 100 | I29: % | J29: LBR | K29: Yes | L29: No | M29: =IF(J29="MTL","Preservation Shop","") | N29: =D29*E29 -> 0 | O29: DELETE | P29: =N29*(1+(H29/100)) -> 0 | Q29: No
A30: =A29 -> Condensation control: Supply and install Wall Mounted Dryaire system & required accessories | C30: =Costing!M31 -> Ducting - round elbow | D30: =Costing!O31 -> 0 | E30: =Costing!Q31 -> 30.63 | F30: Hours | G30: Condensation Labour | H30: =Costing!R31*100 -> 100 | I30: % | J30: LBR | K30: Yes | L30: No | M30: =IF(J30="MTL","Preservation Shop","") | N30: =D30*E30 -> 0 | O30: DELETE | P30: =N30*(1+(H30/100)) -> 0 | Q30: No
A31: =A30 -> Condensation control: Supply and install Wall Mounted Dryaire system & required accessories | C31: =Costing!M32 -> Ducting - round - straight conn | D31: =Costing!O32 -> 0 | E31: =Costing!Q32 -> 30.63 | F31: Hours | G31: Condensation Labour | H31: =Costing!R32*100 -> 100 | I31: % | J31: LBR | K31: Yes | L31: No | M31: =IF(J31="MTL","Preservation Shop","") | N31: =D31*E31 -> 0 | O31: DELETE | P31: =N31*(1+(H31/100)) -> 0 | Q31: No
A32: =A31 -> Condensation control: Supply and install Wall Mounted Dryaire system & required accessories | C32: =Costing!M33 -> Ducting - round 1m | D32: =Costing!O33 -> 0 | E32: =Costing!Q33 -> 30.63 | F32: Hours | G32: Condensation Labour | H32: =Costing!R33*100 -> 100 | I32: % | J32: LBR | K32: Yes | L32: No | M32: =IF(J32="MTL","Preservation Shop","") | N32: =D32*E32 -> 0 | O32: DELETE | P32: =N32*(1+(H32/100)) -> 0 | Q32: No
A33: =A32 -> Condensation control: Supply and install Wall Mounted Dryaire system & required accessories | C33: =Costing!M34 -> Ducting - flat to round adaptor | D33: =Costing!O34 -> 0 | E33: =Costing!Q34 -> 30.63 | F33: Hours | G33: Condensation Labour | H33: =Costing!R34*100 -> 100 | I33: % | J33: LBR | K33: Yes | L33: No | M33: =IF(J33="MTL","Preservation Shop","") | N33: =D33*E33 -> 0 | O33: DELETE | P33: =N33*(1+(H33/100)) -> 0 | Q33: No
A34: =A33 -> Condensation control: Supply and install Wall Mounted Dryaire system & required accessories | C34: =Costing!M35 -> Ducting - flat straight connector | D34: =Costing!O35 -> 0 | E34: =Costing!Q35 -> 30.63 | F34: Hours | G34: Condensation Labour | H34: =Costing!R35*100 -> 100 | I34: % | J34: LBR | K34: Yes | L34: No | M34: =IF(J34="MTL","Preservation Shop","") | N34: =D34*E34 -> 0 | O34: DELETE | P34: =N34*(1+(H34/100)) -> 0 | Q34: No
A35: =A34 -> Condensation control: Supply and install Wall Mounted Dryaire system & required accessories | C35: =Costing!M36 -> Ducting - flat horizontal bend | D35: =Costing!O36 -> 0 | E35: =Costing!Q36 -> 30.63 | F35: Hours | G35: Condensation Labour | H35: =Costing!R36*100 -> 100 | I35: % | J35: LBR | K35: Yes | L35: No | M35: =IF(J35="MTL","Preservation Shop","") | N35: =D35*E35 -> 0 | O35: DELETE | P35: =N35*(1+(H35/100)) -> 0 | Q35: No
A36: =A35 -> Condensation control: Supply and install Wall Mounted Dryaire system & required accessories | C36: =Costing!M37 -> Ducting - flat vertical bend | D36: =Costing!O37 -> 0 | E36: =Costing!Q37 -> 30.63 | F36: Hours | G36: Condensation Labour | H36: =Costing!R37*100 -> 100 | I36: % | J36: LBR | K36: Yes | L36: No | M36: =IF(J36="MTL","Preservation Shop","") | N36: =D36*E36 -> 0 | O36: DELETE | P36: =N36*(1+(H36/100)) -> 0 | Q36: No
A37: =A36 -> Condensation control: Supply and install Wall Mounted Dryaire system & required accessories | C37: =Costing!M38 -> Ducting - flat - 1m | D37: =Costing!O38 -> 0 | E37: =Costing!Q38 -> 30.63 | F37: Hours | G37: Condensation Labour | H37: =Costing!R38*100 -> 100 | I37: % | J37: LBR | K37: Yes | L37: No | M37: =IF(J37="MTL","Preservation Shop","") | N37: =D37*E37 -> 0 | O37: DELETE | P37: =N37*(1+(H37/100)) -> 0 | Q37: No
A38: =A37 -> Condensation control: Supply and install Wall Mounted Dryaire system & required accessories | C38: =Costing!M39 -> Ducting - insulated flexi (3m Length) | D38: =Costing!O39 -> 0 | E38: =Costing!Q39 -> 30.63 | F38: Hours | G38: Condensation Labour | H38: =Costing!R39*100 -> 100 | I38: % | J38: LBR | K38: Yes | L38: No | M38: =IF(J38="MTL","Preservation Shop","") | N38: =D38*E38 -> 0 | O38: DELETE | P38: =N38*(1+(H38/100)) -> 0 | Q38: No
... A40: =A39 -> Condensation control: Supply and install Wall Mounted Dryaire system & required accessories | C40: =Costing!M41 -> Diamond core 107mm hole | D40: =Costing!O41 -> 0 | E40: =Costing!Q41 -> 30.63 | F40: Hours | G40: Condensation Labour | H40: =Costing!R41*100 -> 100 | I40: % | J40: LBR | K40: Yes | L40: No | M40: =IF(J40="MTL","Preservation Shop","") | N40: =D40*E40 -> 0 | O40: DELETE | P40: =N40*(1+(H40/100)) -> 0 | Q40: No
A41: =A40 -> Condensation control: Supply and install Wall Mounted Dryaire system & required accessories | C41: =_xlfn.CONCAT(A41," - Materials") -> Condensation control: Supply and install Wall Mounted Dryaire system & required accessories - Materials | D41: 1 | E41: =N41 -> 0 | F41: EACH | G41: Condensation Materials | H41: =((P41-N41)/N41)*100 -> #DIV/0! | I41: % | J41: MTL | K41: Yes | L41: ='Customer Summary'!D5 -> No | M41: =IF(J41="MTL","Preservation Shop","") -> Preservation Shop | N41: =SUM(N13:N26) -> 0 | O41: =IF(N41=0,"DELETE","LEAVE") -> DELETE | P41: =SUM(P13:P26) -> 0 | Q41: Yes
...

Sheet Data Lists
A1: Data Lists For Contractor Foreman
A3: These are used to differentiate between the types of items and used for the labor calculations.
A4: Contractor Foreman Item Types
A5: Item | B5: Comments
A6: EQUIP | B6: Equipment Items
A7: LBR | B7: Labor items
A8: MTL | B8: Material Items
A9: Other | B9: Other Items
A10: SUB | B10: Subcontractors
A12: This is used to 'Group' items in a logical order on the estimate.
A13: Sections
A14: Item | B14: Comments
A15: ='Customer Summary'!C4 -> Condensation control: Supply and install Loft Dryaire system & required accessories | B15: n/a
A16: ='Customer Summary'!C5 -> Condensation control: Supply and install Wall Mounted Dryaire system & required accessories | B16: n/a
A17: ='Customer Summary'!C6 -> Condensation control: Supply and install Trickle & Boost Fan | B17: n/a
A18: ='Customer Summary'!C7 -> Condensation control: Supply and install Dryaire Cpass Insulated Pullcord Passive Vent | B18: n/a
A19: ='Customer Summary'!C8 -> Condensation control: Supply and install Dryaire CVent | B19: n/a
A20: ='Customer Summary'!C14 -> Airbricks | B20: n/a
A21: ='Customer Summary'!C9 -> Joinery: Supply and fit boxwork for ducting | B21: n/a
A22: ='Customer Summary'!C10 -> New hatch and ladder: Create larger opening, install new sturdy hatch and ladder to loft entry | B22: n/a
A23: ='Customer Summary'!C11 -> Loft opening: Enlarge existing loft opening and install new hatch lid | B23: n/a
A24: ='Customer Summary'!C12 -> Remedial treatments: Mould treatment | B24: n/a
A25: ='Customer Summary'!C13 -> Asbestos Testing | B25: n/a
A26: ='Customer Summary'!C15 -> Project Specific Overheads | B26: n/a
A33: This is used in the projects to determine costs by the 'Cost Code' category (lets you see which areas you are over or under budget on).
A34: Cost Codes
A35: Item | B35: Comments
A36: Condensation Equipment | B36: n/a
A37: Condensation Labour | B37: n/a
A38: Condensation Materials | B38: n/a
A39: Condensation Other | B39: n/a
A40: Condensation Sub Contractors | B40: n/a
A41: Travel Costs | B41: n/a
A42: Waste Removal | B42: n/a
A45: This is used to on the items for costing reference
A46: Unit of measures
A47: Item | B47: Comments
A48: Each | B48: n/a
A49: M2 | B49: n/a
A50: M3 | B50: n/a
...

Sheet Changes
A1: Date | B1: Version From | C1: Version To | D1: Change
A2: 45393 | B2: 17 | C2: 18 | D2: Add VBA to updated the file name (date) on each click as the file names only changed on open so if clicking multiple times it was trying to save the same file again which is confusing)
A3: 45393 | B3: 17 | C3: 18 | D3: Added Sub Contractor 'clarity' section on costing sheet - Vat registered and non vat registered
A4: 45425 | B4: 18 | C4: 19 | D4: Added the word trunking along with ducting etc.
A5: 45440 | B5: 19 | C5: 20 | D5: Changed ambiguous wording to roof vents to 'Customer to …'.
A6: 45440 | B6: 19 | C6: 20 | D6: Added deposit value ex vat and inc vat for card readers.
A7: 45460 | B7: 20 | C7: 21 | D7: Added Section Price Adjustment %.
A8: 45489 | B8: 21 | C8: 22 | D8: Added external defects & airbricks section to the report.
A9: 45491 | B9: 22 | C9: 23 | D9: Re-arranged the external defects section to be put at the bottom of the report.
A10: 45495 | B10: 23 | C10: 24 | D10: Fixed conditional logic issue which was showing a row on the report when it shouldn't have been.
A11: 45539 | B11: 25 | C11: 26 | D11: Added conditional logic to Defects section on report so that it pre-populates more cells as requested by GH. Also removed the Office comments section at the bottom of the report as it is hiiden when the filter is applied so this is replaced with an 'Office Notes' tab.
A12: 45562 | B12: 26 | C12: 27 | D12: Changed wording on Projects Specific Overheads to make it look more generic and to cover more areas and removed the vehicle costs statement. Added the On Site Approval Form Tab.
A13: 45600 | B13: 27 | C13: 28 | D13: Increased rate from £30 to £30.63 to cover for Employers NI increase.
... A22: 45974 | B22: 36 | C22: 37 | D22: Updated master password.
